[2024-11-20T03:10:02.619+0000] {taskinstance.py:1979} INFO - Dependencies all met for dep_context=non-requeueable deps ti=<TaskInstance: customer_metrics.audit_customer_transactions manual__2024-11-20T03:08:35.870567+00:00 [queued]>
[2024-11-20T03:10:02.626+0000] {taskinstance.py:1979} INFO - Dependencies all met for dep_context=requeueable deps ti=<TaskInstance: customer_metrics.audit_customer_transactions manual__2024-11-20T03:08:35.870567+00:00 [queued]>
[2024-11-20T03:10:02.627+0000] {taskinstance.py:2193} INFO - Starting attempt 1 of 1
[2024-11-20T03:10:02.638+0000] {taskinstance.py:2214} INFO - Executing <Task(_PythonExternalDecoratedOperator): audit_customer_transactions> on 2024-11-20 03:08:35.870567+00:00
[2024-11-20T03:10:02.643+0000] {standard_task_runner.py:60} INFO - Started process 9002 to run task
[2024-11-20T03:10:02.645+0000] {standard_task_runner.py:87} INFO - Running: ['airflow', 'tasks', 'run', 'customer_metrics', 'audit_customer_transactions', 'manual__2024-11-20T03:08:35.870567+00:00', '--job-id', '102', '--raw', '--subdir', 'DAGS_FOLDER/customer_metrics.py', '--cfg-path', '/tmp/tmpy58j519b']
[2024-11-20T03:10:02.646+0000] {standard_task_runner.py:88} INFO - Job 102: Subtask audit_customer_transactions
[2024-11-20T03:10:02.687+0000] {task_command.py:423} INFO - Running <TaskInstance: customer_metrics.audit_customer_transactions manual__2024-11-20T03:08:35.870567+00:00 [running]> on host 4cf1ca1acf00
[2024-11-20T03:10:02.754+0000] {taskinstance.py:2510} INFO - Exporting env vars: AIRFLOW_CTX_DAG_OWNER='airflow' AIRFLOW_CTX_DAG_ID='customer_metrics' AIRFLOW_CTX_TASK_ID='audit_customer_transactions' AIRFLOW_CTX_EXECUTION_DATE='2024-11-20T03:08:35.870567+00:00' AIRFLOW_CTX_TRY_NUMBER='1' AIRFLOW_CTX_DAG_RUN_ID='manual__2024-11-20T03:08:35.870567+00:00'
[2024-11-20T03:10:02.786+0000] {python.py:913} WARNING - When checking for Airflow installed in virtual environment got Command '['/opt/airflow/soda_venv/bin/python', '-c', 'from airflow import __version__; print(__version__)']' returned non-zero exit status 1.
[2024-11-20T03:10:02.787+0000] {python.py:914} WARNING - This means that Airflow is not properly installed by  /opt/airflow/soda_venv/bin/python. Airflow context keys will not be available. Please Install Airflow 2.8.2 in your environment to access them.
[2024-11-20T03:10:02.833+0000] {process_utils.py:182} INFO - Executing cmd: /opt/airflow/soda_venv/bin/python /tmp/venv-callebxi097e/script.py /tmp/venv-callebxi097e/script.in /tmp/venv-callebxi097e/script.out /tmp/venv-callebxi097e/string_args.txt /tmp/venv-callebxi097e/termination.log
[2024-11-20T03:10:02.839+0000] {process_utils.py:186} INFO - Output:
[2024-11-20T03:10:03.255+0000] {process_utils.py:190} INFO - [03:10:03] Path "include/soda/checks/tables" does not exist
[2024-11-20T03:10:03.255+0000] {process_utils.py:190} INFO - [03:10:03] No valid checks found, 0 checks evaluated.
[2024-11-20T03:10:03.256+0000] {process_utils.py:190} INFO - [03:10:03] Path "include/soda/checks/tables" does not exist
[2024-11-20T03:10:03.268+0000] {process_utils.py:190} INFO - Running Soda Scan ...
[2024-11-20T03:10:03.269+0000] {process_utils.py:190} INFO - INFO   | Soda Core 3.2.2
[2024-11-20T03:10:03.270+0000] {process_utils.py:190} INFO - DEBUG  | Reading configuration file "include/soda/configuration.yml"
[2024-11-20T03:10:03.271+0000] {process_utils.py:190} INFO - ERROR  | Path "include/soda/checks/tables" does not exist
[2024-11-20T03:10:03.272+0000] {process_utils.py:190} INFO - DEBUG  | Scan execution starts
[2024-11-20T03:10:03.272+0000] {process_utils.py:190} INFO - INFO   | Scan summary:
[2024-11-20T03:10:03.272+0000] {process_utils.py:190} INFO - WARNING| No valid checks found, 0 checks evaluated.
[2024-11-20T03:10:03.273+0000] {process_utils.py:190} INFO - INFO   | 1 errors.
[2024-11-20T03:10:03.273+0000] {process_utils.py:190} INFO - INFO   | Oops! 1 error. 0 failures. 0 warnings. 0 pass.
[2024-11-20T03:10:03.273+0000] {process_utils.py:190} INFO - Traceback (most recent call last):
[2024-11-20T03:10:03.273+0000] {process_utils.py:190} INFO -   File "/tmp/venv-callebxi097e/script.py", line 47, in <module>
[2024-11-20T03:10:03.274+0000] {process_utils.py:190} INFO -     res = audit_customer_transactions(*arg_dict["args"], **arg_dict["kwargs"])
[2024-11-20T03:10:03.274+0000] {process_utils.py:190} INFO -   File "/tmp/venv-callebxi097e/script.py", line 20, in audit_customer_transactions
[2024-11-20T03:10:03.274+0000] {process_utils.py:190} INFO -     check(scan_name, checks_subpath, data_source)
[2024-11-20T03:10:03.275+0000] {process_utils.py:190} INFO -   File "/opt/airflow/include/soda/helpers.py", line 22, in check
[2024-11-20T03:10:03.275+0000] {process_utils.py:190} INFO -     raise ValueError('Soda Scan failed')
[2024-11-20T03:10:03.275+0000] {process_utils.py:190} INFO - ValueError: Soda Scan failed
[2024-11-20T03:10:03.319+0000] {taskinstance.py:2728} ERROR - Task failed with exception
Traceback (most recent call last):
  File "/home/airflow/.local/lib/python3.8/site-packages/airflow/models/taskinstance.py", line 444, in _execute_task
    result = _execute_callable(context=context, **execute_callable_kwargs)
  File "/home/airflow/.local/lib/python3.8/site-packages/airflow/models/taskinstance.py", line 414, in _execute_callable
    return execute_callable(context=context, **execute_callable_kwargs)
  File "/home/airflow/.local/lib/python3.8/site-packages/airflow/decorators/base.py", line 241, in execute
    return_value = super().execute(context)
  File "/home/airflow/.local/lib/python3.8/site-packages/airflow/operators/python.py", line 401, in execute
    return super().execute(context=serializable_context)
  File "/home/airflow/.local/lib/python3.8/site-packages/airflow/operators/python.py", line 200, in execute
    return_value = self.execute_callable()
  File "/home/airflow/.local/lib/python3.8/site-packages/airflow/operators/python.py", line 861, in execute_callable
    return self._execute_python_callable_in_subprocess(python_path)
  File "/home/airflow/.local/lib/python3.8/site-packages/airflow/operators/python.py", line 478, in _execute_python_callable_in_subprocess
    raise AirflowException(error_msg) from None
airflow.exceptions.AirflowException: Process returned non-zero exit status 1.
Soda Scan failed
[2024-11-20T03:10:03.322+0000] {taskinstance.py:1149} INFO - Marking task as FAILED. dag_id=customer_metrics, task_id=audit_customer_transactions, execution_date=20241120T030835, start_date=20241120T031002, end_date=20241120T031003
[2024-11-20T03:10:03.336+0000] {standard_task_runner.py:107} ERROR - Failed to execute job 102 for task audit_customer_transactions (Process returned non-zero exit status 1.
Soda Scan failed; 9002)
[2024-11-20T03:10:03.379+0000] {local_task_job_runner.py:234} INFO - Task exited with return code 1
[2024-11-20T03:10:03.408+0000] {taskinstance.py:3309} INFO - 0 downstream tasks scheduled from follow-on schedule check
