[2024-11-20T03:49:14.034+0000] {taskinstance.py:1979} INFO - Dependencies all met for dep_context=non-requeueable deps ti=<TaskInstance: customer_metrics.publish.customer_transactions_run manual__2024-11-20T03:47:11.945088+00:00 [queued]>
[2024-11-20T03:49:14.043+0000] {taskinstance.py:1979} INFO - Dependencies all met for dep_context=requeueable deps ti=<TaskInstance: customer_metrics.publish.customer_transactions_run manual__2024-11-20T03:47:11.945088+00:00 [queued]>
[2024-11-20T03:49:14.044+0000] {taskinstance.py:2193} INFO - Starting attempt 1 of 1
[2024-11-20T03:49:14.059+0000] {taskinstance.py:2214} INFO - Executing <Task(DbtRunLocalOperator): publish.customer_transactions_run> on 2024-11-20 03:47:11.945088+00:00
[2024-11-20T03:49:14.063+0000] {standard_task_runner.py:60} INFO - Started process 12901 to run task
[2024-11-20T03:49:14.066+0000] {standard_task_runner.py:87} INFO - Running: ['airflow', 'tasks', 'run', 'customer_metrics', 'publish.customer_transactions_run', 'manual__2024-11-20T03:47:11.945088+00:00', '--job-id', '127', '--raw', '--subdir', 'DAGS_FOLDER/customer_metrics.py', '--cfg-path', '/tmp/tmp7lz289p2']
[2024-11-20T03:49:14.068+0000] {standard_task_runner.py:88} INFO - Job 127: Subtask publish.customer_transactions_run
[2024-11-20T03:49:14.115+0000] {task_command.py:423} INFO - Running <TaskInstance: customer_metrics.publish.customer_transactions_run manual__2024-11-20T03:47:11.945088+00:00 [running]> on host 4cf1ca1acf00
[2024-11-20T03:49:14.200+0000] {taskinstance.py:2510} INFO - Exporting env vars: AIRFLOW_CTX_DAG_OWNER='airflow' AIRFLOW_CTX_DAG_ID='customer_metrics' AIRFLOW_CTX_TASK_ID='publish.customer_transactions_run' AIRFLOW_CTX_EXECUTION_DATE='2024-11-20T03:47:11.945088+00:00' AIRFLOW_CTX_TRY_NUMBER='1' AIRFLOW_CTX_DAG_RUN_ID='manual__2024-11-20T03:47:11.945088+00:00'
[2024-11-20T03:49:14.201+0000] {local.py:202} INFO - Cloning project to writable temp directory /tmp/tmpxicnhup7 from /opt/airflow/include/dbt/fraud
[2024-11-20T03:49:14.205+0000] {config.py:253} INFO - Using user-supplied profiles.yml at /opt/airflow/include/dbt/fraud/profiles.yml
[2024-11-20T03:49:14.205+0000] {local.py:235} INFO - Trying to run the command:
 ['/home/airflow/.local/bin/dbt', 'run', '--models', 'customer_transactions', '--profiles-dir', '/opt/airflow/include/dbt/fraud', '--profile', 'fraud', '--target', 'dev']
From /tmp/tmpxicnhup7
[2024-11-20T03:49:14.206+0000] {local.py:236} INFO - Using environment variables keys: dict_keys(['AIRFLOW_CTX_DAG_OWNER', 'AIRFLOW_CTX_DAG_ID', 'AIRFLOW_CTX_TASK_ID', 'AIRFLOW_CTX_EXECUTION_DATE', 'AIRFLOW_CTX_TRY_NUMBER', 'AIRFLOW_CTX_DAG_RUN_ID'])
[2024-11-20T03:49:14.206+0000] {subprocess.py:60} INFO - Tmp dir root location: 
 /tmp
[2024-11-20T03:49:14.207+0000] {subprocess.py:73} INFO - Running command: ['/home/airflow/.local/bin/dbt', 'run', '--models', 'customer_transactions', '--profiles-dir', '/opt/airflow/include/dbt/fraud', '--profile', 'fraud', '--target', 'dev']
[2024-11-20T03:49:14.215+0000] {subprocess.py:84} INFO - Command output:
[2024-11-20T03:49:15.867+0000] {subprocess.py:94} INFO - [0m03:49:15  Running with dbt=1.8.7
[2024-11-20T03:49:16.952+0000] {subprocess.py:94} INFO - [0m03:49:16  Registered adapter: snowflake=1.8.4
[2024-11-20T03:49:16.980+0000] {subprocess.py:94} INFO - [0m03:49:16  Unable to do partial parsing because saved manifest not found. Starting full parse.
[2024-11-20T03:49:18.587+0000] {subprocess.py:94} INFO - [0m03:49:18  Found 3 models, 454 macros
[2024-11-20T03:49:18.589+0000] {subprocess.py:94} INFO - [0m03:49:18
[2024-11-20T03:49:22.388+0000] {subprocess.py:94} INFO - [0m03:49:22  Concurrency: 1 threads (target='dev')
[2024-11-20T03:49:22.389+0000] {subprocess.py:94} INFO - [0m03:49:22
[2024-11-20T03:49:22.396+0000] {subprocess.py:94} INFO - [0m03:49:22  1 of 1 START sql table model AIRBYTE_SCHEMA.customer_transactions .............. [RUN]
[2024-11-20T03:49:24.109+0000] {subprocess.py:94} INFO - [0m03:49:24  1 of 1 ERROR creating sql table model AIRBYTE_SCHEMA.customer_transactions ..... [[31mERROR[0m in 1.71s]
[2024-11-20T03:49:24.112+0000] {subprocess.py:94} INFO - [0m03:49:24
[2024-11-20T03:49:24.113+0000] {subprocess.py:94} INFO - [0m03:49:24  Finished running 1 table model in 0 hours 0 minutes and 5.52 seconds (5.52s).
[2024-11-20T03:49:24.152+0000] {subprocess.py:94} INFO - [0m03:49:24
[2024-11-20T03:49:24.152+0000] {subprocess.py:94} INFO - [0m03:49:24  [31mCompleted with 1 error and 0 warnings:[0m
[2024-11-20T03:49:24.153+0000] {subprocess.py:94} INFO - [0m03:49:24
[2024-11-20T03:49:24.153+0000] {subprocess.py:94} INFO - [0m03:49:24    Database Error in model customer_transactions (models/customer_transactions.sql)
[2024-11-20T03:49:24.154+0000] {subprocess.py:94} INFO -   000904 (42000): SQL compilation error: error line 3 at position 41
[2024-11-20T03:49:24.154+0000] {subprocess.py:94} INFO -   invalid identifier 'TRANSACTIONS_DATE'
[2024-11-20T03:49:24.155+0000] {subprocess.py:94} INFO -   compiled code at target/run/fraud/models/customer_transactions.sql
[2024-11-20T03:49:24.155+0000] {subprocess.py:94} INFO - [0m03:49:24
[2024-11-20T03:49:24.156+0000] {subprocess.py:94} INFO - [0m03:49:24  Done. PASS=0 WARN=0 ERROR=1 SKIP=0 TOTAL=1
[2024-11-20T03:49:25.372+0000] {subprocess.py:98} INFO - Command exited with return code 1
[2024-11-20T03:49:25.383+0000] {local.py:138} WARNING - Artifact schema version: https://schemas.getdbt.com/dbt/manifest/v12.json is above dbt-ol supported version 7. This might cause errors.
[2024-11-20T03:49:25.384+0000] {local.py:138} WARNING - Artifact schema version: https://schemas.getdbt.com/dbt/run-results/v6.json is above dbt-ol supported version 5. This might cause errors.
[2024-11-20T03:49:25.390+0000] {local.py:252} INFO - Inlets: []
[2024-11-20T03:49:25.391+0000] {local.py:253} INFO - Outlets: []
[2024-11-20T03:49:25.391+0000] {dag.py:3047} INFO - Sync 1 DAGs
[2024-11-20T03:49:25.417+0000] {dag.py:3834} INFO - Setting next_dagrun for customer_metrics to 2024-11-20 00:00:00+00:00, run_after=2024-11-21 00:00:00+00:00
[2024-11-20T03:49:25.447+0000] {taskinstance.py:2728} ERROR - Task failed with exception
Traceback (most recent call last):
  File "/home/airflow/.local/lib/python3.8/site-packages/airflow/models/taskinstance.py", line 444, in _execute_task
    result = _execute_callable(context=context, **execute_callable_kwargs)
  File "/home/airflow/.local/lib/python3.8/site-packages/airflow/models/taskinstance.py", line 414, in _execute_callable
    return execute_callable(context=context, **execute_callable_kwargs)
  File "/home/airflow/.local/lib/python3.8/site-packages/cosmos/operators/base.py", line 246, in execute
    self.build_and_run_cmd(context=context, cmd_flags=self.add_cmd_flags())
  File "/home/airflow/.local/lib/python3.8/site-packages/cosmos/operators/local.py", line 370, in build_and_run_cmd
    result = self.run_command(cmd=dbt_cmd, env=env, context=context)
  File "/home/airflow/.local/lib/python3.8/site-packages/cosmos/operators/local.py", line 257, in run_command
    self.exception_handling(result)
  File "/home/airflow/.local/lib/python3.8/site-packages/cosmos/operators/local.py", line 136, in exception_handling
    raise AirflowException(
airflow.exceptions.AirflowException: ('dbt command failed. The command returned a non-zero exit code 1. Details: ', '\x1b[0m03:49:15  Running with dbt=1.8.7', '\x1b[0m03:49:16  Registered adapter: snowflake=1.8.4', '\x1b[0m03:49:16  Unable to do partial parsing because saved manifest not found. Starting full parse.', '\x1b[0m03:49:18  Found 3 models, 454 macros', '\x1b[0m03:49:18', "\x1b[0m03:49:22  Concurrency: 1 threads (target='dev')", '\x1b[0m03:49:22', '\x1b[0m03:49:22  1 of 1 START sql table model AIRBYTE_SCHEMA.customer_transactions .............. [RUN]', '\x1b[0m03:49:24  1 of 1 ERROR creating sql table model AIRBYTE_SCHEMA.customer_transactions ..... [\x1b[31mERROR\x1b[0m in 1.71s]', '\x1b[0m03:49:24', '\x1b[0m03:49:24  Finished running 1 table model in 0 hours 0 minutes and 5.52 seconds (5.52s).', '\x1b[0m03:49:24', '\x1b[0m03:49:24  \x1b[31mCompleted with 1 error and 0 warnings:\x1b[0m', '\x1b[0m03:49:24', '\x1b[0m03:49:24    Database Error in model customer_transactions (models/customer_transactions.sql)', '  000904 (42000): SQL compilation error: error line 3 at position 41', "  invalid identifier 'TRANSACTIONS_DATE'", '  compiled code at target/run/fraud/models/customer_transactions.sql', '\x1b[0m03:49:24', '\x1b[0m03:49:24  Done. PASS=0 WARN=0 ERROR=1 SKIP=0 TOTAL=1')
[2024-11-20T03:49:25.451+0000] {taskinstance.py:1149} INFO - Marking task as FAILED. dag_id=customer_metrics, task_id=publish.customer_transactions_run, execution_date=20241120T034711, start_date=20241120T034914, end_date=20241120T034925
[2024-11-20T03:49:25.461+0000] {standard_task_runner.py:107} ERROR - Failed to execute job 127 for task publish.customer_transactions_run (('dbt command failed. The command returned a non-zero exit code 1. Details: ', '\x1b[0m03:49:15  Running with dbt=1.8.7', '\x1b[0m03:49:16  Registered adapter: snowflake=1.8.4', '\x1b[0m03:49:16  Unable to do partial parsing because saved manifest not found. Starting full parse.', '\x1b[0m03:49:18  Found 3 models, 454 macros', '\x1b[0m03:49:18', "\x1b[0m03:49:22  Concurrency: 1 threads (target='dev')", '\x1b[0m03:49:22', '\x1b[0m03:49:22  1 of 1 START sql table model AIRBYTE_SCHEMA.customer_transactions .............. [RUN]', '\x1b[0m03:49:24  1 of 1 ERROR creating sql table model AIRBYTE_SCHEMA.customer_transactions ..... [\x1b[31mERROR\x1b[0m in 1.71s]', '\x1b[0m03:49:24', '\x1b[0m03:49:24  Finished running 1 table model in 0 hours 0 minutes and 5.52 seconds (5.52s).', '\x1b[0m03:49:24', '\x1b[0m03:49:24  \x1b[31mCompleted with 1 error and 0 warnings:\x1b[0m', '\x1b[0m03:49:24', '\x1b[0m03:49:24    Database Error in model customer_transactions (models/customer_transactions.sql)', '  000904 (42000): SQL compilation error: error line 3 at position 41', "  invalid identifier 'TRANSACTIONS_DATE'", '  compiled code at target/run/fraud/models/customer_transactions.sql', '\x1b[0m03:49:24', '\x1b[0m03:49:24  Done. PASS=0 WARN=0 ERROR=1 SKIP=0 TOTAL=1'); 12901)
[2024-11-20T03:49:25.484+0000] {local_task_job_runner.py:234} INFO - Task exited with return code 1
[2024-11-20T03:49:25.498+0000] {taskinstance.py:3309} INFO - 0 downstream tasks scheduled from follow-on schedule check
