[2024-11-20T03:25:16.005+0000] {taskinstance.py:1979} INFO - Dependencies all met for dep_context=non-requeueable deps ti=<TaskInstance: customer_metrics.publish.customer_transactions_run manual__2024-11-20T03:23:08.473931+00:00 [queued]>
[2024-11-20T03:25:16.015+0000] {taskinstance.py:1979} INFO - Dependencies all met for dep_context=requeueable deps ti=<TaskInstance: customer_metrics.publish.customer_transactions_run manual__2024-11-20T03:23:08.473931+00:00 [queued]>
[2024-11-20T03:25:16.015+0000] {taskinstance.py:2193} INFO - Starting attempt 1 of 1
[2024-11-20T03:25:16.029+0000] {taskinstance.py:2214} INFO - Executing <Task(DbtRunLocalOperator): publish.customer_transactions_run> on 2024-11-20 03:23:08.473931+00:00
[2024-11-20T03:25:16.033+0000] {standard_task_runner.py:60} INFO - Started process 10666 to run task
[2024-11-20T03:25:16.036+0000] {standard_task_runner.py:87} INFO - Running: ['airflow', 'tasks', 'run', 'customer_metrics', 'publish.customer_transactions_run', 'manual__2024-11-20T03:23:08.473931+00:00', '--job-id', '116', '--raw', '--subdir', 'DAGS_FOLDER/customer_metrics.py', '--cfg-path', '/tmp/tmpiwiv3dyh']
[2024-11-20T03:25:16.037+0000] {standard_task_runner.py:88} INFO - Job 116: Subtask publish.customer_transactions_run
[2024-11-20T03:25:16.082+0000] {task_command.py:423} INFO - Running <TaskInstance: customer_metrics.publish.customer_transactions_run manual__2024-11-20T03:23:08.473931+00:00 [running]> on host 4cf1ca1acf00
[2024-11-20T03:25:16.156+0000] {taskinstance.py:2510} INFO - Exporting env vars: AIRFLOW_CTX_DAG_OWNER='airflow' AIRFLOW_CTX_DAG_ID='customer_metrics' AIRFLOW_CTX_TASK_ID='publish.customer_transactions_run' AIRFLOW_CTX_EXECUTION_DATE='2024-11-20T03:23:08.473931+00:00' AIRFLOW_CTX_TRY_NUMBER='1' AIRFLOW_CTX_DAG_RUN_ID='manual__2024-11-20T03:23:08.473931+00:00'
[2024-11-20T03:25:16.158+0000] {local.py:202} INFO - Cloning project to writable temp directory /tmp/tmp3_sbga_6 from /opt/airflow/include/dbt/fraud
[2024-11-20T03:25:16.162+0000] {config.py:253} INFO - Using user-supplied profiles.yml at /opt/airflow/include/dbt/fraud/profiles.yml
[2024-11-20T03:25:16.163+0000] {local.py:235} INFO - Trying to run the command:
 ['/home/airflow/.local/bin/dbt', 'run', '--models', 'customer_transactions', '--profiles-dir', '/opt/airflow/include/dbt/fraud', '--profile', 'fraud', '--target', 'dev']
From /tmp/tmp3_sbga_6
[2024-11-20T03:25:16.163+0000] {local.py:236} INFO - Using environment variables keys: dict_keys(['AIRFLOW_CTX_DAG_OWNER', 'AIRFLOW_CTX_DAG_ID', 'AIRFLOW_CTX_TASK_ID', 'AIRFLOW_CTX_EXECUTION_DATE', 'AIRFLOW_CTX_TRY_NUMBER', 'AIRFLOW_CTX_DAG_RUN_ID'])
[2024-11-20T03:25:16.164+0000] {subprocess.py:60} INFO - Tmp dir root location: 
 /tmp
[2024-11-20T03:25:16.164+0000] {subprocess.py:73} INFO - Running command: ['/home/airflow/.local/bin/dbt', 'run', '--models', 'customer_transactions', '--profiles-dir', '/opt/airflow/include/dbt/fraud', '--profile', 'fraud', '--target', 'dev']
[2024-11-20T03:25:16.172+0000] {subprocess.py:84} INFO - Command output:
[2024-11-20T03:25:17.751+0000] {subprocess.py:94} INFO - [0m03:25:17  Running with dbt=1.8.7
[2024-11-20T03:25:18.854+0000] {subprocess.py:94} INFO - [0m03:25:18  Registered adapter: snowflake=1.8.4
[2024-11-20T03:25:18.884+0000] {subprocess.py:94} INFO - [0m03:25:18  Unable to do partial parsing because saved manifest not found. Starting full parse.
[2024-11-20T03:25:20.825+0000] {subprocess.py:94} INFO - [0m03:25:20  Found 3 models, 454 macros
[2024-11-20T03:25:20.828+0000] {subprocess.py:94} INFO - [0m03:25:20
[2024-11-20T03:25:24.151+0000] {subprocess.py:94} INFO - [0m03:25:24  Concurrency: 1 threads (target='dev')
[2024-11-20T03:25:24.152+0000] {subprocess.py:94} INFO - [0m03:25:24
[2024-11-20T03:25:24.158+0000] {subprocess.py:94} INFO - [0m03:25:24  1 of 1 START sql table model AIRBYTE_SCHEMA.customer_transactions .............. [RUN]
[2024-11-20T03:25:26.070+0000] {subprocess.py:94} INFO - [0m03:25:26  1 of 1 ERROR creating sql table model AIRBYTE_SCHEMA.customer_transactions ..... [[31mERROR[0m in 1.91s]
[2024-11-20T03:25:26.073+0000] {subprocess.py:94} INFO - [0m03:25:26
[2024-11-20T03:25:26.074+0000] {subprocess.py:94} INFO - [0m03:25:26  Finished running 1 table model in 0 hours 0 minutes and 5.24 seconds (5.24s).
[2024-11-20T03:25:26.108+0000] {subprocess.py:94} INFO - [0m03:25:26
[2024-11-20T03:25:26.109+0000] {subprocess.py:94} INFO - [0m03:25:26  [31mCompleted with 1 error and 0 warnings:[0m
[2024-11-20T03:25:26.109+0000] {subprocess.py:94} INFO - [0m03:25:26
[2024-11-20T03:25:26.110+0000] {subprocess.py:94} INFO - [0m03:25:26    Database Error in model customer_transactions (models/customer_transactions.sql)
[2024-11-20T03:25:26.110+0000] {subprocess.py:94} INFO -   000904 (42000): SQL compilation error: error line 3 at position 41
[2024-11-20T03:25:26.111+0000] {subprocess.py:94} INFO -   invalid identifier 'TRANSACTIONS_DATE'
[2024-11-20T03:25:26.111+0000] {subprocess.py:94} INFO -   compiled code at target/run/fraud/models/customer_transactions.sql
[2024-11-20T03:25:26.112+0000] {subprocess.py:94} INFO - [0m03:25:26
[2024-11-20T03:25:26.112+0000] {subprocess.py:94} INFO - [0m03:25:26  Done. PASS=0 WARN=0 ERROR=1 SKIP=0 TOTAL=1
[2024-11-20T03:25:27.359+0000] {subprocess.py:98} INFO - Command exited with return code 1
[2024-11-20T03:25:27.371+0000] {local.py:138} WARNING - Artifact schema version: https://schemas.getdbt.com/dbt/manifest/v12.json is above dbt-ol supported version 7. This might cause errors.
[2024-11-20T03:25:27.372+0000] {local.py:138} WARNING - Artifact schema version: https://schemas.getdbt.com/dbt/run-results/v6.json is above dbt-ol supported version 5. This might cause errors.
[2024-11-20T03:25:27.378+0000] {local.py:252} INFO - Inlets: []
[2024-11-20T03:25:27.378+0000] {local.py:253} INFO - Outlets: []
[2024-11-20T03:25:27.379+0000] {dag.py:3047} INFO - Sync 1 DAGs
[2024-11-20T03:25:27.403+0000] {dag.py:3834} INFO - Setting next_dagrun for customer_metrics to 2024-11-20 00:00:00+00:00, run_after=2024-11-21 00:00:00+00:00
[2024-11-20T03:25:27.433+0000] {taskinstance.py:2728} ERROR - Task failed with exception
Traceback (most recent call last):
  File "/home/airflow/.local/lib/python3.8/site-packages/airflow/models/taskinstance.py", line 444, in _execute_task
    result = _execute_callable(context=context, **execute_callable_kwargs)
  File "/home/airflow/.local/lib/python3.8/site-packages/airflow/models/taskinstance.py", line 414, in _execute_callable
    return execute_callable(context=context, **execute_callable_kwargs)
  File "/home/airflow/.local/lib/python3.8/site-packages/cosmos/operators/base.py", line 246, in execute
    self.build_and_run_cmd(context=context, cmd_flags=self.add_cmd_flags())
  File "/home/airflow/.local/lib/python3.8/site-packages/cosmos/operators/local.py", line 370, in build_and_run_cmd
    result = self.run_command(cmd=dbt_cmd, env=env, context=context)
  File "/home/airflow/.local/lib/python3.8/site-packages/cosmos/operators/local.py", line 257, in run_command
    self.exception_handling(result)
  File "/home/airflow/.local/lib/python3.8/site-packages/cosmos/operators/local.py", line 136, in exception_handling
    raise AirflowException(
airflow.exceptions.AirflowException: ('dbt command failed. The command returned a non-zero exit code 1. Details: ', '\x1b[0m03:25:17  Running with dbt=1.8.7', '\x1b[0m03:25:18  Registered adapter: snowflake=1.8.4', '\x1b[0m03:25:18  Unable to do partial parsing because saved manifest not found. Starting full parse.', '\x1b[0m03:25:20  Found 3 models, 454 macros', '\x1b[0m03:25:20', "\x1b[0m03:25:24  Concurrency: 1 threads (target='dev')", '\x1b[0m03:25:24', '\x1b[0m03:25:24  1 of 1 START sql table model AIRBYTE_SCHEMA.customer_transactions .............. [RUN]', '\x1b[0m03:25:26  1 of 1 ERROR creating sql table model AIRBYTE_SCHEMA.customer_transactions ..... [\x1b[31mERROR\x1b[0m in 1.91s]', '\x1b[0m03:25:26', '\x1b[0m03:25:26  Finished running 1 table model in 0 hours 0 minutes and 5.24 seconds (5.24s).', '\x1b[0m03:25:26', '\x1b[0m03:25:26  \x1b[31mCompleted with 1 error and 0 warnings:\x1b[0m', '\x1b[0m03:25:26', '\x1b[0m03:25:26    Database Error in model customer_transactions (models/customer_transactions.sql)', '  000904 (42000): SQL compilation error: error line 3 at position 41', "  invalid identifier 'TRANSACTIONS_DATE'", '  compiled code at target/run/fraud/models/customer_transactions.sql', '\x1b[0m03:25:26', '\x1b[0m03:25:26  Done. PASS=0 WARN=0 ERROR=1 SKIP=0 TOTAL=1')
[2024-11-20T03:25:27.437+0000] {taskinstance.py:1149} INFO - Marking task as FAILED. dag_id=customer_metrics, task_id=publish.customer_transactions_run, execution_date=20241120T032308, start_date=20241120T032516, end_date=20241120T032527
[2024-11-20T03:25:27.449+0000] {standard_task_runner.py:107} ERROR - Failed to execute job 116 for task publish.customer_transactions_run (('dbt command failed. The command returned a non-zero exit code 1. Details: ', '\x1b[0m03:25:17  Running with dbt=1.8.7', '\x1b[0m03:25:18  Registered adapter: snowflake=1.8.4', '\x1b[0m03:25:18  Unable to do partial parsing because saved manifest not found. Starting full parse.', '\x1b[0m03:25:20  Found 3 models, 454 macros', '\x1b[0m03:25:20', "\x1b[0m03:25:24  Concurrency: 1 threads (target='dev')", '\x1b[0m03:25:24', '\x1b[0m03:25:24  1 of 1 START sql table model AIRBYTE_SCHEMA.customer_transactions .............. [RUN]', '\x1b[0m03:25:26  1 of 1 ERROR creating sql table model AIRBYTE_SCHEMA.customer_transactions ..... [\x1b[31mERROR\x1b[0m in 1.91s]', '\x1b[0m03:25:26', '\x1b[0m03:25:26  Finished running 1 table model in 0 hours 0 minutes and 5.24 seconds (5.24s).', '\x1b[0m03:25:26', '\x1b[0m03:25:26  \x1b[31mCompleted with 1 error and 0 warnings:\x1b[0m', '\x1b[0m03:25:26', '\x1b[0m03:25:26    Database Error in model customer_transactions (models/customer_transactions.sql)', '  000904 (42000): SQL compilation error: error line 3 at position 41', "  invalid identifier 'TRANSACTIONS_DATE'", '  compiled code at target/run/fraud/models/customer_transactions.sql', '\x1b[0m03:25:26', '\x1b[0m03:25:26  Done. PASS=0 WARN=0 ERROR=1 SKIP=0 TOTAL=1'); 10666)
[2024-11-20T03:25:27.472+0000] {local_task_job_runner.py:234} INFO - Task exited with return code 1
[2024-11-20T03:25:27.486+0000] {taskinstance.py:3309} INFO - 0 downstream tasks scheduled from follow-on schedule check
